<sdf version='1.7'>
  <world name='default'>
    <light name='sun' type='directional'>
      <cast_shadows>1</cast_shadows>
      <pose>0 0 10 0 -0 0</pose>
      <diffuse>0.8 0.8 0.8 1</diffuse>
      <specular>0.2 0.2 0.2 1</specular>
      <attenuation>
        <range>1000</range>
        <constant>0.9</constant>
        <linear>0.01</linear>
        <quadratic>0.001</quadratic>
      </attenuation>
      <direction>-0.5 0.1 -0.9</direction>
      <spot>
        <inner_angle>0</inner_angle>
        <outer_angle>0</outer_angle>
        <falloff>0</falloff>
      </spot>
    </light>
    <model name='ground_plane'>
      <static>1</static>
      <link name='link'>
        <collision name='collision'>
          <geometry>
            <plane>
              <normal>0 0 1</normal>
              <size>100 100</size>
            </plane>
          </geometry>
          <surface>
            <contact>
              <collide_bitmask>65535</collide_bitmask>
              <ode/>
            </contact>
            <friction>
              <ode>
                <mu>100</mu>
                <mu2>50</mu2>
              </ode>
              <torsional>
                <ode/>
              </torsional>
            </friction>
            <bounce/>
          </surface>
          <max_contacts>10</max_contacts>
        </collision>
        <visual name='visual'>
          <cast_shadows>0</cast_shadows>
          <geometry>
            <plane>
              <normal>0 0 1</normal>
              <size>100 100</size>
            </plane>
          </geometry>
          <material>
            <script>
              <uri>file://media/materials/scripts/gazebo.material</uri>
              <name>Gazebo/Grey</name>
            </script>
          </material>
        </visual>
        <self_collide>0</self_collide>
        <enable_wind>0</enable_wind>
        <kinematic>0</kinematic>
      </link>
    </model>
    <gravity>0 0 -9.8</gravity>
    <magnetic_field>6e-06 2.3e-05 -4.2e-05</magnetic_field>
    <atmosphere type='adiabatic'/>
    <physics type='ode'>
      <max_step_size>0.001</max_step_size>
      <real_time_factor>1</real_time_factor>
      <real_time_update_rate>1000</real_time_update_rate>
    </physics>
    <scene>
      <ambient>0.4 0.4 0.4 1</ambient>
      <background>0.7 0.7 0.7 1</background>
      <shadows>1</shadows>
    </scene>
    <wind/>
    <spherical_coordinates>
      <surface_model>EARTH_WGS84</surface_model>
      <latitude_deg>0</latitude_deg>
      <longitude_deg>0</longitude_deg>
      <elevation>0</elevation>
      <heading_deg>0</heading_deg>
    </spherical_coordinates>
    <model name='Autonomous'>
      <link name='base_link'>
        <inertial>
          <pose>0.004069 0.00053 0.159766 0 -0 0</pose>
          <mass>243.578</mass>
          <inertia>
            <ixx>3.71483</ixx>
            <ixy>-0.0104782</ixy>
            <ixz>-0.117297</ixz>
            <iyy>6.55168</iyy>
            <iyz>-0.0172105</iyz>
            <izz>7.95273</izz>
          </inertia>
        </inertial>
        <collision name='base_link_collision'>
          <pose>0 0 0 0 -0 0</pose>
          <geometry>
            <mesh>
              <scale>0.001 0.001 0.001</scale>
              <uri>/home/ogunsina/auto_ws/src/Autonomous_description/meshes/base_link.stl</uri>
            </mesh>
          </geometry>
          <surface>
            <contact>
              <ode/>
            </contact>
            <friction>
              <ode>
                <mu>0.1</mu>
                <mu2>0.1</mu2>
              </ode>
              <torsional>
                <ode/>
              </torsional>
            </friction>
            <bounce/>
          </surface>
          <max_contacts>10</max_contacts>
        </collision>
        <collision name='base_link_fixed_joint_lump__head_plate_1_collision_1'>
          <pose>0 0 0 0 -0 0</pose>
          <geometry>
            <mesh>
              <scale>0.001 0.001 0.001</scale>
              <uri>/home/ogunsina/auto_ws/src/Autonomous_description/meshes/head_plate_1.stl</uri>
            </mesh>
          </geometry>
          <surface>
            <contact>
              <ode/>
            </contact>
            <friction>
              <ode>
                <mu>0.2</mu>
                <mu2>0.2</mu2>
              </ode>
              <torsional>
                <ode/>
              </torsional>
            </friction>
            <bounce/>
          </surface>
          <max_contacts>10</max_contacts>
        </collision>
        <collision name='base_link_fixed_joint_lump__lidar_1_collision_2'>
          <pose>0 0 0 0 -0 0</pose>
          <geometry>
            <mesh>
              <scale>0.001 0.001 0.001</scale>
              <uri>/home/ogunsina/auto_ws/src/Autonomous_description/meshes/lidar_1.stl</uri>
            </mesh>
          </geometry>
          <surface>
            <contact>
              <ode/>
            </contact>
            <friction>
              <ode>
                <mu>0.2</mu>
                <mu2>0.2</mu2>
              </ode>
              <torsional>
                <ode/>
              </torsional>
            </friction>
            <bounce/>
          </surface>
          <max_contacts>10</max_contacts>
        </collision>
        <collision name='base_link_fixed_joint_lump__camera_1_collision_3'>
          <pose>-0 0 0 0 -0 0</pose>
          <geometry>
            <mesh>
              <scale>0.001 0.001 0.001</scale>
              <uri>/home/ogunsina/auto_ws/src/Autonomous_description/meshes/camera_1.stl</uri>
            </mesh>
          </geometry>
          <surface>
            <contact>
              <ode/>
            </contact>
            <friction>
              <ode>
                <mu>0.2</mu>
                <mu2>0.2</mu2>
              </ode>
              <torsional>
                <ode/>
              </torsional>
            </friction>
            <bounce/>
          </surface>
          <max_contacts>10</max_contacts>
        </collision>
        <visual name='base_link_visual'>
          <pose>0 0 0 0 -0 0</pose>
          <geometry>
            <mesh>
              <scale>0.001 0.001 0.001</scale>
              <uri>/home/ogunsina/auto_ws/src/Autonomous_description/meshes/base_link.stl</uri>
            </mesh>
          </geometry>
          <material>
            <script>
              <name>Gazebo/Silver</name>
              <uri>file://media/materials/scripts/gazebo.material</uri>
            </script>
          </material>
        </visual>
        <visual name='base_link_fixed_joint_lump__head_plate_1_visual_1'>
          <pose>0 0 0 0 -0 0</pose>
          <geometry>
            <mesh>
              <scale>0.001 0.001 0.001</scale>
              <uri>/home/ogunsina/auto_ws/src/Autonomous_description/meshes/head_plate_1.stl</uri>
            </mesh>
          </geometry>
          <material>
            <script>
              <name>Gazebo/Silver</name>
              <uri>file://media/materials/scripts/gazebo.material</uri>
            </script>
          </material>
        </visual>
        <visual name='base_link_fixed_joint_lump__lidar_1_visual_2'>
          <pose>0 0 0 0 -0 0</pose>
          <geometry>
            <mesh>
              <scale>0.001 0.001 0.001</scale>
              <uri>/home/ogunsina/auto_ws/src/Autonomous_description/meshes/lidar_1.stl</uri>
            </mesh>
          </geometry>
          <material>
            <script>
              <name>Gazebo/Silver</name>
              <uri>file://media/materials/scripts/gazebo.material</uri>
            </script>
          </material>
        </visual>
        <visual name='base_link_fixed_joint_lump__camera_1_visual_3'>
          <pose>-0 0 0 0 -0 0</pose>
          <geometry>
            <mesh>
              <scale>0.001 0.001 0.001</scale>
              <uri>/home/ogunsina/auto_ws/src/Autonomous_description/meshes/camera_1.stl</uri>
            </mesh>
          </geometry>
          <material>
            <script>
              <name>Gazebo/Silver</name>
              <uri>file://media/materials/scripts/gazebo.material</uri>
            </script>
          </material>
        </visual>
        <velocity_decay/>
        <velocity_decay/>
        <velocity_decay/>
        <velocity_decay/>
        <sensor name='head_hokuyo_sensor' type='ray'>
          <visualize>1</visualize>
          <update_rate>40</update_rate>
          <ray>
            <scan>
              <horizontal>
                <samples>720</samples>
                <resolution>1</resolution>
                <min_angle>-1.5708</min_angle>
                <max_angle>1.5708</max_angle>
              </horizontal>
              <vertical>
                <samples>1</samples>
                <min_angle>0</min_angle>
                <max_angle>0</max_angle>
              </vertical>
            </scan>
            <range>
              <min>0.1</min>
              <max>30</max>
              <resolution>0.01</resolution>
            </range>
            <noise>
              <type>gaussian</type>
              <mean>0</mean>
              <stddev>0.01</stddev>
            </noise>
          </ray>
          <plugin name='gazebo_ros_head_hokuyo_controller' filename='libgazebo_ros_laser.so'>
            <topicName>/scan</topicName>
            <frameName>lidar_1</frameName>
            <robotNamespace>/</robotNamespace>
          </plugin>
          <pose>0.286443 -0.129544 0.3 0 -0 0</pose>
        </sensor>
        <gravity>1</gravity>
        <velocity_decay/>
        <self_collide>1</self_collide>
        <gravity>1</gravity>
        <velocity_decay/>
        <gravity>1</gravity>
        <sensor name='imu_sensor' type='imu'>
          <always_on>1</always_on>
          <update_rate>100</update_rate>
          <visualize>1</visualize>
          <topic>/imu</topic>
          <plugin name='imu_plugin' filename='libgazebo_ros_imu_sensor.so'>
            <topicName>imu</topicName>
            <bodyName>camera_1</bodyName>
            <updateRateHZ>10.0</updateRateHZ>
            <gaussianNoise>0.0</gaussianNoise>
            <xyzOffset>0 0 0</xyzOffset>
            <rpyOffset>0 0 0</rpyOffset>
            <frameName>camera_1</frameName>
            <initialOrientationAsReference>0</initialOrientationAsReference>
            <robotNamespace>/</robotNamespace>
          </plugin>
          <pose>0.189761 -0.076346 0.27 0 -0 0</pose>
          <imu/>
        </sensor>
        <enable_wind>0</enable_wind>
        <kinematic>0</kinematic>
      </link>
      <joint name='Rev2' type='revolute'>
        <pose relative_to='base_link'>-0.175 -0.2315 0.051428 0 -0 0</pose>
        <parent>base_link</parent>
        <child>leftwheel1_1</child>
        <axis>
          <xyz>0 1 0</xyz>
          <limit>
            <lower>-1e+16</lower>
            <upper>1e+16</upper>
          </limit>
          <dynamics>
            <spring_reference>0</spring_reference>
            <spring_stiffness>0</spring_stiffness>
          </dynamics>
        </axis>
      </joint>
      <link name='leftwheel1_1'>
        <pose relative_to='Rev2'>0 0 0 0 -0 0</pose>
        <inertial>
          <pose>-0 0.017601 -0 0 -0 0</pose>
          <mass>28.5062</mass>
          <inertia>
            <ixx>0.136487</ixx>
            <ixy>0</ixy>
            <ixz>0</ixz>
            <iyy>0.241289</iyy>
            <iyz>0</iyz>
            <izz>0.136487</izz>
          </inertia>
        </inertial>
        <collision name='leftwheel1_1_collision'>
          <pose>0.175 0.2315 -0.051428 0 -0 0</pose>
          <geometry>
            <mesh>
              <scale>0.001 0.001 0.001</scale>
              <uri>/home/ogunsina/auto_ws/src/Autonomous_description/meshes/leftwheel1_1.stl</uri>
            </mesh>
          </geometry>
          <surface>
            <contact>
              <ode/>
            </contact>
            <friction>
              <ode>
                <mu>1500</mu>
                <mu2>1500</mu2>
              </ode>
              <torsional>
                <ode/>
              </torsional>
            </friction>
            <bounce/>
          </surface>
          <max_contacts>10</max_contacts>
        </collision>
        <visual name='leftwheel1_1_visual'>
          <pose>0.175 0.2315 -0.051428 0 -0 0</pose>
          <geometry>
            <mesh>
              <scale>0.001 0.001 0.001</scale>
              <uri>/home/ogunsina/auto_ws/src/Autonomous_description/meshes/leftwheel1_1.stl</uri>
            </mesh>
          </geometry>
          <material>
            <script>
              <name>Gazebo/Silver</name>
              <uri>file://media/materials/scripts/gazebo.material</uri>
            </script>
          </material>
        </visual>
        <gravity>1</gravity>
        <velocity_decay/>
        <self_collide>1</self_collide>
        <enable_wind>0</enable_wind>
        <kinematic>0</kinematic>
      </link>
      <joint name='Rev3' type='revolute'>
        <pose relative_to='base_link'>0.175 -0.2315 0.051428 0 -0 0</pose>
        <parent>base_link</parent>
        <child>leftwheel2_1</child>
        <axis>
          <xyz>0 1 0</xyz>
          <limit>
            <lower>-1e+16</lower>
            <upper>1e+16</upper>
          </limit>
          <dynamics>
            <spring_reference>0</spring_reference>
            <spring_stiffness>0</spring_stiffness>
          </dynamics>
        </axis>
      </joint>
      <link name='leftwheel2_1'>
        <pose relative_to='Rev3'>0 0 0 0 -0 0</pose>
        <inertial>
          <pose>0 0.017668 -0 0 -0 0</pose>
          <mass>28.6967</mass>
          <inertia>
            <ixx>0.138023</ixx>
            <ixy>0</ixy>
            <ixz>0</ixz>
            <iyy>0.244287</iyy>
            <iyz>0</iyz>
            <izz>0.138023</izz>
          </inertia>
        </inertial>
        <collision name='leftwheel2_1_collision'>
          <pose>-0.175 0.2315 -0.051428 0 -0 0</pose>
          <geometry>
            <mesh>
              <scale>0.001 0.001 0.001</scale>
              <uri>/home/ogunsina/auto_ws/src/Autonomous_description/meshes/leftwheel2_1.stl</uri>
            </mesh>
          </geometry>
          <surface>
            <contact>
              <ode/>
            </contact>
            <friction>
              <ode>
                <mu>0.2</mu>
                <mu2>0.2</mu2>
              </ode>
              <torsional>
                <ode/>
              </torsional>
            </friction>
            <bounce/>
          </surface>
          <max_contacts>10</max_contacts>
        </collision>
        <visual name='leftwheel2_1_visual'>
          <pose>-0.175 0.2315 -0.051428 0 -0 0</pose>
          <geometry>
            <mesh>
              <scale>0.001 0.001 0.001</scale>
              <uri>/home/ogunsina/auto_ws/src/Autonomous_description/meshes/leftwheel2_1.stl</uri>
            </mesh>
          </geometry>
          <material>
            <script>
              <name>Gazebo/Silver</name>
              <uri>file://media/materials/scripts/gazebo.material</uri>
            </script>
          </material>
        </visual>
        <gravity>1</gravity>
        <velocity_decay/>
        <self_collide>1</self_collide>
        <enable_wind>0</enable_wind>
        <kinematic>0</kinematic>
      </link>
      <joint name='Rev4' type='revolute'>
        <pose relative_to='base_link'>-0.175 0.2315 0.053213 0 -0 0</pose>
        <parent>base_link</parent>
        <child>rightwheel1_1</child>
        <axis>
          <xyz>0 1 0</xyz>
          <limit>
            <lower>-1e+16</lower>
            <upper>1e+16</upper>
          </limit>
          <dynamics>
            <spring_reference>0</spring_reference>
            <spring_stiffness>0</spring_stiffness>
          </dynamics>
        </axis>
      </joint>
      <link name='rightwheel1_1'>
        <pose relative_to='Rev4'>0 0 0 0 -0 0</pose>
        <inertial>
          <pose>0 -0.017696 0 0 -0 0</pose>
          <mass>28.7062</mass>
          <inertia>
            <ixx>0.138087</ixx>
            <ixy>0</ixy>
            <ixz>0</ixz>
            <iyy>0.244397</iyy>
            <iyz>0</iyz>
            <izz>0.138087</izz>
          </inertia>
        </inertial>
        <collision name='rightwheel1_1_collision'>
          <pose>0.175 -0.2315 -0.053213 0 -0 0</pose>
          <geometry>
            <mesh>
              <scale>0.001 0.001 0.001</scale>
              <uri>/home/ogunsina/auto_ws/src/Autonomous_description/meshes/rightwheel1_1.stl</uri>
            </mesh>
          </geometry>
          <surface>
            <contact>
              <ode/>
            </contact>
            <friction>
              <ode>
                <mu>1500</mu>
                <mu2>1500</mu2>
              </ode>
              <torsional>
                <ode/>
              </torsional>
            </friction>
            <bounce/>
          </surface>
          <max_contacts>10</max_contacts>
        </collision>
        <visual name='rightwheel1_1_visual'>
          <pose>0.175 -0.2315 -0.053213 0 -0 0</pose>
          <geometry>
            <mesh>
              <scale>0.001 0.001 0.001</scale>
              <uri>/home/ogunsina/auto_ws/src/Autonomous_description/meshes/rightwheel1_1.stl</uri>
            </mesh>
          </geometry>
          <material>
            <script>
              <name>Gazebo/Silver</name>
              <uri>file://media/materials/scripts/gazebo.material</uri>
            </script>
          </material>
        </visual>
        <gravity>1</gravity>
        <velocity_decay/>
        <self_collide>1</self_collide>
        <enable_wind>0</enable_wind>
        <kinematic>0</kinematic>
      </link>
      <joint name='Rev5' type='revolute'>
        <pose relative_to='base_link'>0.175 0.2315 0.053213 0 -0 0</pose>
        <parent>base_link</parent>
        <child>rightwheel2_1</child>
        <axis>
          <xyz>0 1 0</xyz>
          <limit>
            <lower>-1e+16</lower>
            <upper>1e+16</upper>
          </limit>
          <dynamics>
            <spring_reference>0</spring_reference>
            <spring_stiffness>0</spring_stiffness>
          </dynamics>
        </axis>
      </joint>
      <link name='rightwheel2_1'>
        <pose relative_to='Rev5'>0 0 0 0 -0 0</pose>
        <inertial>
          <pose>-0 -0.017657 0 0 -0 0</pose>
          <mass>28.689</mass>
          <inertia>
            <ixx>0.137953</ixx>
            <ixy>0</ixy>
            <ixz>0</ixz>
            <iyy>0.244154</iyy>
            <iyz>0</iyz>
            <izz>0.137953</izz>
          </inertia>
        </inertial>
        <collision name='rightwheel2_1_collision'>
          <pose>-0.175 -0.2315 -0.053213 0 -0 0</pose>
          <geometry>
            <mesh>
              <scale>0.001 0.001 0.001</scale>
              <uri>/home/ogunsina/auto_ws/src/Autonomous_description/meshes/rightwheel2_1.stl</uri>
            </mesh>
          </geometry>
          <surface>
            <contact>
              <ode/>
            </contact>
            <friction>
              <ode>
                <mu>0.2</mu>
                <mu2>0.2</mu2>
              </ode>
              <torsional>
                <ode/>
              </torsional>
            </friction>
            <bounce/>
          </surface>
          <max_contacts>10</max_contacts>
        </collision>
        <visual name='rightwheel2_1_visual'>
          <pose>-0.175 -0.2315 -0.053213 0 -0 0</pose>
          <geometry>
            <mesh>
              <scale>0.001 0.001 0.001</scale>
              <uri>/home/ogunsina/auto_ws/src/Autonomous_description/meshes/rightwheel2_1.stl</uri>
            </mesh>
          </geometry>
          <material>
            <script>
              <name>Gazebo/Silver</name>
              <uri>file://media/materials/scripts/gazebo.material</uri>
            </script>
          </material>
        </visual>
        <gravity>1</gravity>
        <velocity_decay/>
        <self_collide>1</self_collide>
        <enable_wind>0</enable_wind>
        <kinematic>0</kinematic>
      </link>
      <plugin name='control' filename='libgazebo_ros_control.so'>
        <robotNamespace>/</robotNamespace>
      </plugin>
      <static>0</static>
      <plugin name='differential_drive_controller' filename='libgazebo_ros_diff_drive.so'>
        <legacyMode>0</legacyMode>
        <alwaysOn>1</alwaysOn>
        <updateRate>20</updateRate>
        <leftJoint>Rev2</leftJoint>
        <rightJoint>Rev3</rightJoint>
        <wheelSeparation>0.4</wheelSeparation>
        <wheelDiameter>0.1</wheelDiameter>
        <torque>20</torque>
        <commandTopic>cmd_vel</commandTopic>
        <odometryTopic>odom</odometryTopic>
        <odometryFrame>odom</odometryFrame>
        <robotBaseFrame>base_link</robotBaseFrame>
        <robotNamespace>/</robotNamespace>
      </plugin>
      <pose>0 0 0 0 -0 0</pose>
    </model>
    <model name='wworld'>
      <pose>0.455 -1.585 0 0 -0 0</pose>
      <link name='Wall_0'>
        <collision name='Wall_0_Collision'>
          <geometry>
            <box>
              <size>13 0.15 2.5</size>
            </box>
          </geometry>
          <pose>0 0 1.25 0 -0 0</pose>
          <max_contacts>10</max_contacts>
          <surface>
            <contact>
              <ode/>
            </contact>
            <bounce/>
            <friction>
              <torsional>
                <ode/>
              </torsional>
              <ode/>
            </friction>
          </surface>
        </collision>
        <visual name='Wall_0_Visual'>
          <pose>0 0 1.25 0 -0 0</pose>
          <geometry>
            <box>
              <size>13 0.15 2.5</size>
            </box>
          </geometry>
          <material>
            <script>
              <uri>file://media/materials/scripts/gazebo.material</uri>
              <name>Gazebo/Grey</name>
            </script>
            <ambient>1 1 1 1</ambient>
          </material>
          <meta>
            <layer>0</layer>
          </meta>
        </visual>
        <pose>-0 -3.225 0 0 -0 0</pose>
        <self_collide>0</self_collide>
        <enable_wind>0</enable_wind>
        <kinematic>0</kinematic>
      </link>
      <link name='Wall_1'>
        <collision name='Wall_1_Collision'>
          <geometry>
            <box>
              <size>4.75 0.15 2.5</size>
            </box>
          </geometry>
          <pose>0 0 1.25 0 -0 0</pose>
          <max_contacts>10</max_contacts>
          <surface>
            <contact>
              <ode/>
            </contact>
            <bounce/>
            <friction>
              <torsional>
                <ode/>
              </torsional>
              <ode/>
            </friction>
          </surface>
        </collision>
        <visual name='Wall_1_Visual'>
          <pose>0 0 1.25 0 -0 0</pose>
          <geometry>
            <box>
              <size>4.75 0.15 2.5</size>
            </box>
          </geometry>
          <material>
            <script>
              <uri>file://media/materials/scripts/gazebo.material</uri>
              <name>Gazebo/Grey</name>
            </script>
            <ambient>1 1 1 1</ambient>
          </material>
          <meta>
            <layer>0</layer>
          </meta>
        </visual>
        <pose>6.425 -0.925 0 0 -0 1.5708</pose>
        <self_collide>0</self_collide>
        <enable_wind>0</enable_wind>
        <kinematic>0</kinematic>
      </link>
      <link name='Wall_2'>
        <collision name='Wall_2_Collision'>
          <geometry>
            <box>
              <size>3.5 0.15 2.5</size>
            </box>
          </geometry>
          <pose>0 0 1.25 0 -0 0</pose>
          <max_contacts>10</max_contacts>
          <surface>
            <contact>
              <ode/>
            </contact>
            <bounce/>
            <friction>
              <torsional>
                <ode/>
              </torsional>
              <ode/>
            </friction>
          </surface>
        </collision>
        <visual name='Wall_2_Visual'>
          <pose>0 0 1.25 0 -0 0</pose>
          <geometry>
            <box>
              <size>3.5 0.15 2.5</size>
            </box>
          </geometry>
          <material>
            <script>
              <uri>file://media/materials/scripts/gazebo.material</uri>
              <name>Gazebo/Grey</name>
            </script>
            <ambient>1 1 1 1</ambient>
          </material>
          <meta>
            <layer>0</layer>
          </meta>
        </visual>
        <pose>4.75 1.375 0 0 -0 3.14159</pose>
        <self_collide>0</self_collide>
        <enable_wind>0</enable_wind>
        <kinematic>0</kinematic>
      </link>
      <link name='Wall_4'>
        <collision name='Wall_4_Collision'>
          <geometry>
            <box>
              <size>2 0.15 2.5</size>
            </box>
          </geometry>
          <pose>0 0 1.25 0 -0 0</pose>
          <max_contacts>10</max_contacts>
          <surface>
            <contact>
              <ode/>
            </contact>
            <bounce/>
            <friction>
              <torsional>
                <ode/>
              </torsional>
              <ode/>
            </friction>
          </surface>
        </collision>
        <visual name='Wall_4_Visual'>
          <pose>0 0 1.25 0 -0 0</pose>
          <geometry>
            <box>
              <size>2 0.15 2.5</size>
            </box>
          </geometry>
          <material>
            <script>
              <uri>file://media/materials/scripts/gazebo.material</uri>
              <name>Gazebo/Grey</name>
            </script>
            <ambient>1 1 1 1</ambient>
          </material>
          <meta>
            <layer>0</layer>
          </meta>
        </visual>
        <pose>3.075 2.3 0 0 -0 1.5708</pose>
        <self_collide>0</self_collide>
        <enable_wind>0</enable_wind>
        <kinematic>0</kinematic>
      </link>
      <link name='Wall_5'>
        <collision name='Wall_5_Collision'>
          <geometry>
            <box>
              <size>8.5 0.15 2.5</size>
            </box>
          </geometry>
          <pose>0 0 1.25 0 -0 0</pose>
          <max_contacts>10</max_contacts>
          <surface>
            <contact>
              <ode/>
            </contact>
            <bounce/>
            <friction>
              <torsional>
                <ode/>
              </torsional>
              <ode/>
            </friction>
          </surface>
        </collision>
        <visual name='Wall_5_Visual'>
          <pose>0 0 1.25 0 -0 0</pose>
          <geometry>
            <box>
              <size>8.5 0.15 2.5</size>
            </box>
          </geometry>
          <material>
            <script>
              <uri>file://media/materials/scripts/gazebo.material</uri>
              <name>Gazebo/Grey</name>
            </script>
            <ambient>1 1 1 1</ambient>
          </material>
          <meta>
            <layer>0</layer>
          </meta>
        </visual>
        <pose>-1.1 3.225 0 0 -0 3.14159</pose>
        <self_collide>0</self_collide>
        <enable_wind>0</enable_wind>
        <kinematic>0</kinematic>
      </link>
      <link name='Wall_7'>
        <collision name='Wall_7_Collision'>
          <geometry>
            <box>
              <size>3.5 0.15 2.5</size>
            </box>
          </geometry>
          <pose>0 0 1.25 0 -0 0</pose>
          <max_contacts>10</max_contacts>
          <surface>
            <contact>
              <ode/>
            </contact>
            <bounce/>
            <friction>
              <torsional>
                <ode/>
              </torsional>
              <ode/>
            </friction>
          </surface>
        </collision>
        <visual name='Wall_7_Visual'>
          <pose>0 0 1.25 0 -0 0</pose>
          <geometry>
            <box>
              <size>3.5 0.15 2.5</size>
            </box>
          </geometry>
          <material>
            <script>
              <uri>file://media/materials/scripts/gazebo.material</uri>
              <name>Gazebo/Grey</name>
            </script>
            <ambient>1 1 1 1</ambient>
          </material>
          <meta>
            <layer>0</layer>
          </meta>
        </visual>
        <pose>-5.275 1.55 0 0 -0 -1.5708</pose>
        <self_collide>0</self_collide>
        <enable_wind>0</enable_wind>
        <kinematic>0</kinematic>
      </link>
      <static>1</static>
    </model>
    <model name='first_2015_trash_can'>
      <link name='link'>
        <inertial>
          <pose>0 0 0.3683 0 -0 0</pose>
          <mass>4.83076</mass>
          <inertia>
            <ixx>0.281534</ixx>
            <ixy>0</ixy>
            <ixz>0</ixz>
            <iyy>0.281534</iyy>
            <iyz>0</iyz>
            <izz>0.126223</izz>
          </inertia>
        </inertial>
        <visual name='visual'>
          <geometry>
            <mesh>
              <uri>model://first_2015_trash_can/meshes/trash_can.dae</uri>
            </mesh>
          </geometry>
        </visual>
        <collision name='collision'>
          <geometry>
            <mesh>
              <uri>model://first_2015_trash_can/meshes/trash_can.dae</uri>
            </mesh>
          </geometry>
          <max_contacts>10</max_contacts>
          <surface>
            <contact>
              <ode/>
            </contact>
            <bounce/>
            <friction>
              <torsional>
                <ode/>
              </torsional>
              <ode/>
            </friction>
          </surface>
        </collision>
        <self_collide>0</self_collide>
        <enable_wind>0</enable_wind>
        <kinematic>0</kinematic>
      </link>
      <pose>-6.73334 -3.1203 0 0 -0 0</pose>
    </model>
    <model name='first_2015_trash_can_0'>
      <link name='link'>
        <inertial>
          <pose>0 0 0.3683 0 -0 0</pose>
          <mass>4.83076</mass>
          <inertia>
            <ixx>0.281534</ixx>
            <ixy>0</ixy>
            <ixz>0</ixz>
            <iyy>0.281534</iyy>
            <iyz>0</iyz>
            <izz>0.126223</izz>
          </inertia>
        </inertial>
        <visual name='visual'>
          <geometry>
            <mesh>
              <uri>model://first_2015_trash_can/meshes/trash_can.dae</uri>
            </mesh>
          </geometry>
        </visual>
        <collision name='collision'>
          <geometry>
            <mesh>
              <uri>model://first_2015_trash_can/meshes/trash_can.dae</uri>
            </mesh>
          </geometry>
          <max_contacts>10</max_contacts>
          <surface>
            <contact>
              <ode/>
            </contact>
            <bounce/>
            <friction>
              <torsional>
                <ode/>
              </torsional>
              <ode/>
            </friction>
          </surface>
        </collision>
        <self_collide>0</self_collide>
        <enable_wind>0</enable_wind>
        <kinematic>0</kinematic>
      </link>
      <pose>-4.01852 -1.36219 0 0 -0 0</pose>
    </model>
    <light name='user_point_light_0' type='point'>
      <pose>-1.48476 -0.741662 1 0 -0 0</pose>
      <diffuse>0.5 0.5 0.5 1</diffuse>
      <specular>0.1 0.1 0.1 1</specular>
      <attenuation>
        <range>20</range>
        <constant>0.5</constant>
        <linear>0.01</linear>
        <quadratic>0.001</quadratic>
      </attenuation>
      <cast_shadows>0</cast_shadows>
      <direction>0 0 -1</direction>
    </light>
    <state world_name='default'>
      <sim_time>726 549000000</sim_time>
      <real_time>1214 783331855</real_time>
      <wall_time>1639357658 729684233</wall_time>
      <iterations>726549</iterations>
      <model name='Autonomous'>
        <pose>-0.619102 -0.072023 0.080776 -0.005203 -0.001496 -0.061546</pose>
        <scale>1 1 1</scale>
        <link name='base_link'>
          <pose>-0.619102 -0.072023 0.080776 -0.005203 -0.001496 -0.061546</pose>
          <velocity>0.000251 0.001328 1.4e-05 0.022484 -0.000709 0.001857</velocity>
          <acceleration>-0.217514 -4.43947 0.086454 -2.13425 -0.514511 0.977018</acceleration>
          <wrench>-52.9816 -1081.36 21.0584 0 -0 0</wrench>
        </link>
        <link name='leftwheel1_1'>
          <pose>-0.808071 -0.292044 0.133145 -3.13392 0.837394 3.08574</pose>
          <velocity>0.000562 -0.000774 -0.00496 0.006329 0.000288 0.002388</velocity>
          <acceleration>0.626237 -1.53683 -9.69868 0.058259 0.424697 -1.14011</acceleration>
          <wrench>17.8516 -43.8092 -276.473 0 -0 0</wrench>
        </link>
        <link name='leftwheel2_1'>
          <pose>-0.458734 -0.313574 0.13367 -0.010074 -1.02812 -0.052927</pose>
          <velocity>0.000604 0.000431 -0.005374 0.022213 -0.000672 0.001974</velocity>
          <acceleration>0.732614 1.00333 -9.96316 0.463494 -0.962638 -1.97319</acceleration>
          <wrench>21.0236 28.7922 -285.91 0 -0 0</wrench>
        </link>
        <link name='rightwheel1_1'>
          <pose>-0.779592 0.170077 0.132521 -0.005329 0.125255 -0.06222</pose>
          <velocity>-0.0002 -0.000703 0.005252 0.005848 -0.001064 0.001541</velocity>
          <acceleration>-0.916149 -1.39515 10.2995 -0.755728 -1.018 -2.84564</acceleration>
          <wrench>-26.2992 -40.0494 295.659 0 -0 0</wrench>
        </link>
        <link name='rightwheel2_1'>
          <pose>-0.430255 0.148553 0.133045 -3.133 0.920499 3.08688</pose>
          <velocity>-0.00015 0.000509 0.005235 0.022306 -0.000628 0.001808</velocity>
          <acceleration>-0.79797 1.15153 9.68693 -2.52737 0.771127 0.840838</acceleration>
          <wrench>-22.8929 33.0364 277.908 0 -0 0</wrench>
        </link>
      </model>
      <model name='first_2015_trash_can'>
        <pose>-6.73332 -3.1203 -1e-06 -5e-06 7e-06 -0.0001</pose>
        <scale>1 1 1</scale>
        <link name='link'>
          <pose>-6.73332 -3.1203 -1e-06 -5e-06 7e-06 -0.0001</pose>
          <velocity>0 0 0 0 -0 0</velocity>
          <acceleration>6.23211 -0.893816 5.06619 -0.714611 -1.2134 -3.14148</acceleration>
          <wrench>30.1058 -4.31781 24.4735 0 -0 0</wrench>
        </link>
      </model>
      <model name='first_2015_trash_can_0'>
        <pose>-4.0185 -1.36219 -0 1.6e-05 1.3e-05 -6.5e-05</pose>
        <scale>1 1 1</scale>
        <link name='link'>
          <pose>-4.0185 -1.36219 -0 1.6e-05 1.3e-05 -6.5e-05</pose>
          <velocity>0 0 0 0 -0 0</velocity>
          <acceleration>-1.60957 5.68652 4.35921 0.261832 1.22562 3.13705</acceleration>
          <wrench>-7.77546 27.4702 21.0583 0 -0 0</wrench>
        </link>
      </model>
      <model name='ground_plane'>
        <pose>0 0 0 0 -0 0</pose>
        <scale>1 1 1</scale>
        <link name='link'>
          <pose>0 0 0 0 -0 0</pose>
          <velocity>0 0 0 0 -0 0</velocity>
          <acceleration>0 0 0 0 -0 0</acceleration>
          <wrench>0 0 0 0 -0 0</wrench>
        </link>
      </model>
      <model name='wworld'>
        <pose>0.455 -1.585 0 0 -0 0</pose>
        <scale>1 1 1</scale>
        <link name='Wall_0'>
          <pose>0.455 -4.81 0 0 -0 0</pose>
          <velocity>0 0 0 0 -0 0</velocity>
          <acceleration>0 0 0 0 -0 0</acceleration>
          <wrench>0 0 0 0 -0 0</wrench>
        </link>
        <link name='Wall_1'>
          <pose>6.88 -2.51 0 0 -0 1.5708</pose>
          <velocity>0 0 0 0 -0 0</velocity>
          <acceleration>0 0 0 0 -0 0</acceleration>
          <wrench>0 0 0 0 -0 0</wrench>
        </link>
        <link name='Wall_2'>
          <pose>5.205 -0.21 0 0 -0 3.14159</pose>
          <velocity>0 0 0 0 -0 0</velocity>
          <acceleration>0 0 0 0 -0 0</acceleration>
          <wrench>0 0 0 0 -0 0</wrench>
        </link>
        <link name='Wall_4'>
          <pose>3.53 0.715 0 0 -0 1.5708</pose>
          <velocity>0 0 0 0 -0 0</velocity>
          <acceleration>0 0 0 0 -0 0</acceleration>
          <wrench>0 0 0 0 -0 0</wrench>
        </link>
        <link name='Wall_5'>
          <pose>-0.645 1.64 0 0 -0 3.14159</pose>
          <velocity>0 0 0 0 -0 0</velocity>
          <acceleration>0 0 0 0 -0 0</acceleration>
          <wrench>0 0 0 0 -0 0</wrench>
        </link>
        <link name='Wall_7'>
          <pose>-4.82 -0.035 0 0 0 -1.5708</pose>
          <velocity>0 0 0 0 -0 0</velocity>
          <acceleration>0 0 0 0 -0 0</acceleration>
          <wrench>0 0 0 0 -0 0</wrench>
        </link>
      </model>
      <light name='sun'>
        <pose>0 0 10 0 -0 0</pose>
      </light>
      <light name='user_point_light_0'>
        <pose>-1.48476 -0.741662 1 0 -0 0</pose>
      </light>
    </state>
    <gui fullscreen='0'>
      <camera name='user_camera'>
        <pose>-0.467418 2.23609 17.2442 3.14159 1.57079 3.14159</pose>
        <view_controller>orbit</view_controller>
        <projection_type>perspective</projection_type>
      </camera>
    </gui>
  </world>
</sdf>
